<?xml version="1.0" ?>
<robot name="turtlebot3_waffle" xmlns:xacro="http://ros.org/wiki/xacro">

  <link name="base_footprint"/>

  <joint name="base_joint" type="fixed">
    <parent link="base_footprint"/>
    <child link="base_link" />
    <origin xyz="0 0 0.010" rpy="0 0 0"/>
  </joint>

  <gazebo reference="base_link">
    <visual>
      <material>
        <ambient>0.4 0.4 0.4 1</ambient>
        <diffuse>0.4 0.4 0.4 1</diffuse>
        <specular>0.0 0.0 1.0 1</specular>
      </material>
    </visual>
  </gazebo>

  <link name="base_link">
    <visual>
      <origin xyz="-0.064 0 0.0" rpy="0 0 0"/>
      <geometry>
        <mesh filename="package://turtlebot3_gazebo/models/turtlebot3_common/meshes/waffle_base.dae" scale="0.001 0.001 0.001"/>
      </geometry>
    </visual>

    <collision>
      <origin xyz="-0.064 0 0.047" rpy="0 0 0"/>
      <geometry>
        <box size="0.266 0.266 0.094"/>
      </geometry>
    </collision>

    <inertial>
      <origin xyz="0 0 0" rpy="0 0 0"/>
      <mass value="1.0"/>
      <inertia ixx="0.001" ixy="0.0" ixz="0.0"
               iyy="0.001" iyz="0.0"
               izz="0.001" />
    </inertial>
  </link>

  <joint name="wheel_left_joint" type="continuous">
    <parent link="base_link"/>
    <child link="wheel_left_link"/>
    <origin xyz="0.0 0.144 0.023" rpy="-1.57 0 0"/>
    <axis xyz="0 0 1"/>
  </joint>

  <gazebo reference="wheel_left_link">
    <visual>
      <material>
        <ambient>0.3 0.3 0.3 1</ambient>
        <diffuse>0.3 0.3 0.3 1</diffuse>
        <specular>0.0 0.0 1.0 1</specular>
      </material>
    </visual>
  </gazebo>
  <link name="wheel_left_link">
    <visual>
      <origin xyz="0 0 0" rpy="1.57 0 0"/>
      <geometry>
        <mesh filename="package://turtlebot3_gazebo/models/turtlebot3_common/meshes/tire.dae" scale="0.001 0.001 0.001"/>
      </geometry>
    </visual>

    <collision>
      <origin xyz="0 0 0" rpy="0 0 0"/>
      <geometry>
        <cylinder length="0.018" radius="0.033"/>
      </geometry>
      <surface>
        <friction>
          <ode>
            <mu>100000.0</mu>
            <mu2>100000.0</mu2>
            <fdir1>0 0 0</fdir1>
            <slip1>0.0</slip1>
            <slip2>0.0</slip2>
          </ode>
        </friction>
        <contact>
          <ode>
            <soft_cfm>0</soft_cfm>
            <soft_erp>0.2</soft_erp>
            <kp>1e+5</kp>
            <kd>1</kd>
            <max_vel>0.01</max_vel>
            <min_depth>0.001</min_depth>
          </ode>
        </contact>
      </surface>
    </collision>

    <inertial>
      <origin xyz="0 0 0" />
      <mass value="0.1" />
      <inertia ixx="0.001" ixy="0.0" ixz="0.0"
               iyy="0.001" iyz="0.0"
               izz="0.001" />
   </inertial>
  </link>

  <joint name="wheel_right_joint" type="continuous">
    <parent link="base_link"/>
    <child link="wheel_right_link"/>
    <origin xyz="0.0 -0.144 0.023" rpy="-1.57 0 0"/>
    <axis xyz="0 0 1"/>
  </joint>

  <gazebo reference="wheel_right_link">
    <visual>
      <material>
        <ambient>0.3 0.3 0.3 1</ambient>
        <diffuse>0.3 0.3 0.3 1</diffuse>
        <specular>0.0 0.0 1.0 1</specular>
      </material>
    </visual>
  </gazebo>

  <link name="wheel_right_link">
    <visual>
      <origin xyz="0 0 0" rpy="1.57 0 0"/>
      <geometry>
        <mesh filename="package://turtlebot3_gazebo/models/turtlebot3_common/meshes/tire.dae" scale="0.001 0.001 0.001"/>
      </geometry>
    </visual>

    <collision>
      <origin xyz="0 0 0" rpy="0 0 0"/>
      <geometry>
        <cylinder length="0.018" radius="0.033"/>
      </geometry>
      <surface>
        <!-- This friction pamareter don't contain reliable data!! -->
        <friction>
          <ode>
            <mu>100000.0</mu>
            <mu2>100000.0</mu2>
            <fdir1>0 0 0</fdir1>
            <slip1>0.0</slip1>
            <slip2>0.0</slip2>
          </ode>
        </friction>
        <contact>
          <ode>
            <soft_cfm>0</soft_cfm>
            <soft_erp>0.2</soft_erp>
            <kp>1e+5</kp>
            <kd>1</kd>
            <max_vel>0.01</max_vel>
            <min_depth>0.001</min_depth>
          </ode>
        </contact>
      </surface>
    </collision>

    <inertial>
      <origin xyz="0 0 0" />
      <mass value="0.1" />
      <inertia ixx="0.001" ixy="0.0" ixz="0.0"
               iyy="0.001" iyz="0.0"
               izz="0.001" />
    </inertial>
  </link>

  <joint name="caster_back_right_joint" type="fixed">
    <parent link="base_link"/>
    <child link="caster_back_right_link"/>
    <origin xyz="-0.177 -0.064 -0.004" rpy="-1.57 0 0"/>
  </joint>

  <link name="caster_back_right_link">
    <collision>
      <origin xyz="0 0.001 0" rpy="0 0 0"/>
      <geometry>
        <sphere radius="0.005000"/>
      </geometry>
      <surface>
        <contact>
          <ode>
            <soft_cfm>0</soft_cfm>
            <soft_erp>0.2</soft_erp>
            <kp>1e+5</kp>
            <kd>1</kd>
            <max_vel>0.01</max_vel>
            <min_depth>0.001</min_depth>
          </ode>
        </contact>
      </surface>
    </collision>

    <visual>
      <origin xyz="0 0.001 0" rpy="0 0 0"/>
      <geometry>
        <sphere radius="0.005000"/>
      </geometry>
    </visual>

    <inertial>
      <origin xyz="0 0 0" />
      <mass value="0.001" />
      <inertia ixx="0.00001" ixy="0.0" ixz="0.0"
               iyy="0.00001" iyz="0.0"
               izz="0.00001" />
    </inertial>
  </link>

  <joint name="caster_back_left_joint" type="fixed">
    <parent link="base_link"/>
    <child link="caster_back_left_link"/>
    <origin xyz="-0.177 0.064 -0.004" rpy="-1.57 0 0"/>
  </joint>

  <link name="caster_back_left_link">
    <collision>
      <origin xyz="0 0.001 0" rpy="0 0 0"/>
      <geometry>
        <sphere radius="0.005000"/>
      </geometry>
      <surface>
        <contact>
          <ode>
            <soft_cfm>0</soft_cfm>
            <soft_erp>0.2</soft_erp>
            <kp>1e+5</kp>
            <kd>1</kd>
            <max_vel>0.01</max_vel>
            <min_depth>0.001</min_depth>
          </ode>
        </contact>
      </surface>
    </collision>

    <visual>
      <origin xyz="0 0.001 0" rpy="0 0 0"/>
      <geometry>
        <sphere radius="0.005000"/>
      </geometry>
    </visual>

    <inertial>
      <origin xyz="0 0 0" />
      <mass value="0.00001" />
      <inertia ixx="0.00001" ixy="0.0" ixz="0.0"
               iyy="0.00001" iyz="0.0"
               izz="0.00001" />
    </inertial>
  </link>

  <joint name="imu_joint" type="fixed">
    <parent link="base_link"/>
    <child link="imu_link"/>
    <origin xyz="0.0 0 0.068" rpy="0 0 0"/>
  </joint>

  <link name="imu_link"/>

  <joint name="scan_joint" type="fixed">
    <parent link="base_link"/>
    <child link="base_scan"/>
    <origin xyz="-0.064 0 0.122" rpy="0 0 0"/>
    <axis xyz="0 0 1"/>
  </joint>

  <gazebo reference="base_scan">
    <visual>
      <material>
        <ambient>0.3 0.3 0.3 1</ambient>
        <diffuse>0.3 0.3 0.3 1</diffuse>
        <specular>0.0 0.0 1.0 1</specular>
      </material>
    </visual>
  </gazebo>

  <link name="base_scan">
    <visual>
      <origin xyz="0 0 0" rpy="0 0 0"/>
      <geometry>
        <mesh filename="package://turtlebot3_gazebo/models/turtlebot3_common/meshes/lds.dae" scale="0.001 0.001 0.001"/>
      </geometry>
    </visual>

    <collision>
      <origin xyz="0.015 0 -0.0065" rpy="0 0 0"/>
      <geometry>
        <cylinder length="0.0315" radius="0.055"/>
      </geometry>
    </collision>

    <inertial>
      <origin xyz="0 0 0" />
      <mass value="0.125" />
      <inertia ixx="0.001" ixy="0.0" ixz="0.0"
               iyy="0.001" iyz="0.0"
               izz="0.001" />
    </inertial>
  </link>

  <joint name="camera_joint" type="fixed">
    <origin xyz="0.064 -0.065 0.094" rpy="0 0 0"/>
    <parent link="base_link"/>
    <child link="camera_link"/>
  </joint>

  <link name="camera_link">
    <visual>
     <origin xyz="0 0 0" rpy="1.57 0 1.57"/>
      <geometry>
        <mesh filename="package://turtlebot3_gazebo/models/turtlebot3_common/meshes/r200.dae" />
      </geometry>
    </visual>
    <collision>
      <origin xyz="0.003 0.065 0.007" rpy="0 0 0"/>
      <geometry>
        <box size="0.012 0.132 0.020"/>
      </geometry>
    </collision>

    <!-- This inertial field needs doesn't contain reliable data!! -->
<!--   <inertial>
      <mass value="0.564" />
      <origin xyz="0 0 0" />
      <inertia ixx="0.003881243" ixy="0.0" ixz="0.0"
               iyy="0.000498940" iyz="0.0"
               izz="0.003879257" />
    </inertial>-->
  </link>

  <joint name="camera_rgb_joint" type="fixed">
    <origin xyz="0.005 0.018 0.013" rpy="0 0 0"/>
    <!-- <origin xyz="${r200_cam_rgb_px} ${r200_cam_rgb_py} ${r200_cam_rgb_pz}" rpy="0 0 0"/> -->
    <parent link="camera_link"/>
    <child link="camera_rgb_frame"/>
  </joint>
  <link name="camera_rgb_frame"/>

  <joint name="camera_rgb_optical_joint" type="fixed">
    <origin xyz="0 0 0" rpy="-1.57 0 -1.57"/>
    <parent link="camera_rgb_frame"/>
    <child link="camera_rgb_optical_frame"/>
  </joint>
  <link name="camera_rgb_optical_frame"/>

  <joint name="camera_depth_joint" type="fixed">
    <origin xyz="0.005 0.028 0.013" rpy="-1.57 0 -1.57"/>
    <!-- <origin xyz="${r200_cam_rgb_px} ${r200_cam_rgb_py + r200_cam_depth_offset} ${r200_cam_rgb_pz}" rpy="0 0 0"/> -->
    <parent link="camera_link"/>
    <child link="camera_depth_frame"/>
  </joint>
  <link name="camera_depth_frame"/>

  <joint name="camera_depth_optical_joint" type="fixed">
    <origin xyz="0 0 0" rpy="0 0 0"/>
    <parent link="camera_depth_frame"/>
    <child link="camera_depth_optical_frame"/>
  </joint>
  <link name="camera_depth_optical_frame"/>

  <gazebo reference="base_scan">
    <sensor name='gpu_lidar' type='gpu_lidar'>"
      <topic>scan</topic>
      <ignition_frame_id>base_scan</ignition_frame_id>
      <pose>-0.064 0 0.121 0 0 0</pose>
      <update_rate>5</update_rate>
      <ray>
        <scan>
          <horizontal>
            <samples>360</samples>
            <resolution>1.000000</resolution>
            <min_angle>0.000000</min_angle>
            <max_angle>6.280000</max_angle>
          </horizontal>
        </scan>
        <range>
          <min>0.120000</min>
          <max>3.5</max>
          <resolution>0.015000</resolution>
        </range>
        <noise>
          <type>gaussian</type>
          <mean>0.0</mean>
          <stddev>0.01</stddev>
        </noise>
      </ray>
      <alwaysOn>1</alwaysOn>
      <visualize>true</visualize>
    </sensor>
  </gazebo>

  <gazebo reference="base_link">
    <sensor name="tb3_imu" type="imu">
      <always_on>true</always_on>
      <update_rate>200</update_rate>
      <topic>imu</topic>
      <ignition_frame_id>imu_link</ignition_frame_id>
      <imu>
        <angular_velocity>
          <x>
            <noise type="gaussian">
              <mean>0.0</mean>
              <stddev>2e-4</stddev>
            </noise>
          </x>
          <y>
            <noise type="gaussian">
              <mean>0.0</mean>
              <stddev>2e-4</stddev>
            </noise>
          </y>
          <z>
            <noise type="gaussian">
              <mean>0.0</mean>
              <stddev>2e-4</stddev>
            </noise>
          </z>
        </angular_velocity>
        <linear_acceleration>
          <x>
            <noise type="gaussian">
              <mean>0.0</mean>
              <stddev>1.7e-2</stddev>
            </noise>
          </x>
          <y>
            <noise type="gaussian">
              <mean>0.0</mean>
              <stddev>1.7e-2</stddev>
            </noise>
          </y>
          <z>
            <noise type="gaussian">
              <mean>0.0</mean>
              <stddev>1.7e-2</stddev>
            </noise>
          </z>
        </linear_acceleration>
      </imu>
    </sensor>
  </gazebo>

  <ros2_control name="GazeboSimSystem" type="system">
    <hardware>
      <plugin>ign_ros2_control/IgnitionSystem</plugin>
    </hardware>
    <joint name="wheel_left_joint">
      <command_interface name="velocity"/>
      <state_interface name="position"/>
      <state_interface name="velocity"/>
    </joint>
    <joint name="wheel_right_joint">
      <command_interface name="velocity"/>
      <state_interface name="position"/>
      <state_interface name="velocity"/>
    </joint>
  </ros2_control>

  <gazebo>
    <plugin filename="ign_ros2_control-system" name="ign_ros2_control::IgnitionROS2ControlPlugin">
      <parameters>$(find nav2_bringup)/params/control.yaml</parameters>
      <ros>
        <remapping>~/odom:=odom</remapping>
        <remapping>/tf:=tf</remapping>
        <remapping>/tf_static:=tf_static</remapping>
        <remapping>/diagnostics:=diagnostics</remapping>
        <remapping>/diffdrive_controller/cmd_vel_unstamped:=cmd_vel</remapping>
      </ros>
    </plugin>

    <plugin
      filename="ignition-gazebo-pose-publisher-system"
      name="ignition::gazebo::systems::PosePublisher">
      <publish_link_pose>true</publish_link_pose>
      <publish_sensor_pose>true</publish_sensor_pose>
      <publish_collision_pose>false</publish_collision_pose>
      <publish_visual_pose>false</publish_visual_pose>
      <publish_nested_model_pose>true</publish_nested_model_pose>
      <static_publisher>true</static_publisher>
      <use_pose_vector_msg>true</use_pose_vector_msg>
    </plugin>
  </gazebo>

</robot>
