<?xml version="1.0" ?>
<robot name="turtlebot3_waffle" xmlns:xacro="http://ros.org/wiki/xacro">
  <link name="base_footprint"/>

  <joint name="base_joint" type="fixed">
    <parent link="base_footprint"/>
    <child link="base_link" />
    <origin xyz="0 0 0.010" rpy="0 0 0"/>
  </joint>

  <gazebo reference="base_link">
    <visual>
      <material>
        <ambient>0.4 0.4 0.4 1</ambient>
        <diffuse>0.4 0.4 0.4 1</diffuse>
        <specular>0.0 0.0 1.0 1</specular>
      </material>
    </visual>
  </gazebo>

  <link name="base_link">
    <visual>
      <origin xyz="-0.064 0 0.0" rpy="0 0 0"/>
      <geometry>
        <mesh filename="package://turtlebot3_gazebo/models/turtlebot3_common/meshes/waffle_base.dae" scale="0.001 0.001 0.001"/>
      </geometry>
    </visual>

    <collision>
      <origin xyz="-0.064 0 0.047" rpy="0 0 0"/>
      <geometry>
        <box size="0.266 0.266 0.094"/>
      </geometry>
    </collision>

    <inertial>
      <origin xyz="0 0 0" rpy="0 0 0"/>
      <mass value="1.3729096e+00"/>
      <inertia ixx="8.7002718e-03" ixy="-4.7576583e-05" ixz="1.1160499e-04"
               iyy="8.6195418e-03" iyz="-3.5422299e-06"
               izz="1.4612727e-02" />
    </inertial>
  </link>

  <joint name="wheel_left_joint" type="continuous">
    <parent link="base_link"/>
    <child link="wheel_left_link"/>
    <origin xyz="0.0 0.144 0.023" rpy="-1.57 0 0"/>
    <axis xyz="0 0 1"/>
  </joint>

  <gazebo reference="wheel_left_link">
    <visual>
      <material>
        <ambient>0.3 0.3 0.3 1</ambient>
        <diffuse>0.3 0.3 0.3 1</diffuse>
        <specular>0.0 0.0 1.0 1</specular>
      </material>
    </visual>
  </gazebo>
  <link name="wheel_left_link">
    <visual>
      <origin xyz="0 0 0" rpy="1.57 0 0"/>
      <geometry>
        <mesh filename="package://turtlebot3_gazebo/models/turtlebot3_common/meshes/tire.dae" scale="0.001 0.001 0.001"/>
      </geometry>
    </visual>

    <collision>
      <origin xyz="0 0 0" rpy="0 0 0"/>
      <geometry>
        <cylinder length="0.018" radius="0.033"/>
      </geometry>
    </collision>

    <inertial>
      <origin xyz="0 0 0" />
      <mass value="2.8498940e-02" />
      <inertia ixx="1.1175580e-05" ixy="-4.2369783e-11" ixz="-5.9381719e-09"
               iyy="1.1192413e-05" iyz="-1.4400107e-11"
               izz="2.0712558e-05" />
      </inertial>
  </link>

  <joint name="wheel_right_joint" type="continuous">
    <parent link="base_link"/>
    <child link="wheel_right_link"/>
    <origin xyz="0.0 -0.144 0.023" rpy="-1.57 0 0"/>
    <axis xyz="0 0 1"/>
  </joint>

  <gazebo reference="wheel_right_link">
    <visual>
      <material>
        <ambient>0.3 0.3 0.3 1</ambient>
        <diffuse>0.3 0.3 0.3 1</diffuse>
        <specular>0.0 0.0 1.0 1</specular>
      </material>
    </visual>
  </gazebo>
  <link name="wheel_right_link">
    <visual>
      <origin xyz="0 0 0" rpy="1.57 0 0"/>
      <geometry>
        <mesh filename="package://turtlebot3_gazebo/models/turtlebot3_common/meshes/tire.dae" scale="0.001 0.001 0.001"/>
      </geometry>
    </visual>

    <collision>
      <origin xyz="0 0 0" rpy="0 0 0"/>
      <geometry>
        <cylinder length="0.018" radius="0.033"/>
      </geometry>
    </collision>

    <inertial>
      <origin xyz="0 0 0" />
      <mass value="2.8498940e-02" />
      <inertia ixx="1.1175580e-05" ixy="-4.2369783e-11" ixz="-5.9381719e-09"
               iyy="1.1192413e-05" iyz="-1.4400107e-11"
               izz="2.0712558e-05" />
      </inertial>
  </link>

  <joint name="caster_back_right_joint" type="fixed">
    <parent link="base_link"/>
    <child link="caster_back_right_link"/>
    <origin xyz="-0.177 -0.064 -0.004" rpy="-1.57 0 0"/>
  </joint>

  <link name="caster_back_right_link">
    <collision>
      <origin xyz="0 0.001 0" rpy="0 0 0"/>
      <geometry>
        <box size="0.030 0.009 0.020"/>
      </geometry>
    </collision>

    <inertial>
      <origin xyz="0 0 0" />
      <mass value="0.005" />
      <inertia ixx="0.001" ixy="0.0" ixz="0.0"
               iyy="0.001" iyz="0.0"
               izz="0.001" />
    </inertial>
  </link>

  <joint name="caster_back_left_joint" type="fixed">
    <parent link="base_link"/>
    <child link="caster_back_left_link"/>
    <origin xyz="-0.177 0.064 -0.004" rpy="-1.57 0 0"/>
  </joint>

  <link name="caster_back_left_link">
    <collision>
      <origin xyz="0 0.001 0" rpy="0 0 0"/>
      <geometry>
        <box size="0.030 0.009 0.020"/>
      </geometry>
    </collision>

    <inertial>
      <origin xyz="0 0 0" />
      <mass value="0.005" />
      <inertia ixx="0.001" ixy="0.0" ixz="0.0"
               iyy="0.001" iyz="0.0"
               izz="0.001" />
    </inertial>
  </link>

  <joint name="imu_joint" type="fixed">
    <parent link="base_link"/>
    <child link="imu_link"/>
    <origin xyz="0.0 0 0.068" rpy="0 0 0"/>
  </joint>

  <link name="imu_link"/>

  <joint name="scan_joint" type="fixed">
    <parent link="base_link"/>
    <child link="base_scan"/>
    <origin xyz="-0.064 0 0.122" rpy="0 0 0"/>
  </joint>

  <gazebo reference="base_scan">
    <visual>
      <material>
        <ambient>0.3 0.3 0.3 1</ambient>
        <diffuse>0.3 0.3 0.3 1</diffuse>
        <specular>0.0 0.0 1.0 1</specular>
      </material>
    </visual>
  </gazebo>

  <link name="base_scan">
    <visual>
      <origin xyz="0 0 0" rpy="0 0 0"/>
      <geometry>
        <mesh filename="package://turtlebot3_gazebo/models/turtlebot3_common/meshes/lds.dae" scale="0.001 0.001 0.001"/>
      </geometry>
    </visual>

    <collision>
      <origin xyz="0.015 0 -0.0065" rpy="0 0 0"/>
      <geometry>
        <cylinder length="0.0315" radius="0.055"/>
      </geometry>
    </collision>

    <inertial>
      <mass value="0.114" />
      <origin xyz="0 0 0" />
      <inertia ixx="0.001" ixy="0.0" ixz="0.0"
               iyy="0.001" iyz="0.0"
               izz="0.001" />
    </inertial>
  </link>

  <joint name="camera_joint" type="fixed">
    <origin xyz="0.064 -0.065 0.094" rpy="0 0 0"/>
    <parent link="base_link"/>
    <child link="camera_link"/>
  </joint>

  <link name="camera_link">
    <visual>
     <origin xyz="0 0 0" rpy="1.57 0 1.57"/>
      <geometry>
        <mesh filename="package://turtlebot3_gazebo/models/turtlebot3_common/meshes/r200.dae" />
      </geometry>
    </visual>
    <collision>
      <origin xyz="0.003 0.065 0.007" rpy="0 0 0"/>
      <geometry>
        <box size="0.012 0.132 0.020"/>
      </geometry>
    </collision>

    <!-- This inertial field needs doesn't contain reliable data!! -->
<!--   <inertial>
      <mass value="0.564" />
      <origin xyz="0 0 0" />
      <inertia ixx="0.003881243" ixy="0.0" ixz="0.0"
               iyy="0.000498940" iyz="0.0"
               izz="0.003879257" />
    </inertial>-->
  </link>

  <joint name="camera_rgb_joint" type="fixed">
    <origin xyz="0.005 0.018 0.013" rpy="0 0 0"/>
    <parent link="camera_link"/>
    <child link="camera_rgb_frame"/>
  </joint>
  <link name="camera_rgb_frame"/>

  <joint name="camera_rgb_optical_joint" type="fixed">
    <origin xyz="0 0 0" rpy="-1.57 0 -1.57"/>
    <parent link="camera_rgb_frame"/>
    <child link="camera_rgb_optical_frame"/>
  </joint>
  <link name="camera_rgb_optical_frame"/>

  <joint name="camera_depth_joint" type="fixed">
    <origin xyz="0.005 0.028 0.013" rpy="-1.57 0 -1.57"/>
    <parent link="camera_link"/>
    <child link="camera_depth_frame"/>
  </joint>
  <link name="camera_depth_frame"/>

  <joint name="camera_depth_optical_joint" type="fixed">
    <origin xyz="0 0 0" rpy="0 0 0"/>
    <parent link="camera_depth_frame"/>
    <child link="camera_depth_optical_frame"/>
  </joint>
  <link name="camera_depth_optical_frame"/>

  <gazebo reference="base_scan">
    <sensor name='gpu_lidar' type='gpu_lidar'>"
      <topic>scan</topic>
      <gz_frame_id>base_scan</gz_frame_id>
      <pose>-0.064 0 0.15 0 0 0</pose>
      <update_rate>5</update_rate>
      <ray>
        <scan>
          <horizontal>
            <samples>360</samples>
            <resolution>1.000000</resolution>
            <min_angle>0.000000</min_angle>
            <max_angle>6.280000</max_angle>
          </horizontal>
          <vertical>
            <samples>1</samples>
            <resolution>0.01</resolution>
            <min_angle>0</min_angle>
            <max_angle>0</max_angle>
          </vertical>
        </scan>
        <range>
          <min>0.00001</min>
          <max>20.0</max>
          <resolution>0.015000</resolution>
        </range>
        <noise>
          <type>gaussian</type>
          <mean>0.0</mean>
          <stddev>0.01</stddev>
        </noise>
      </ray>
    </sensor>
  </gazebo>

  <gazebo reference="base_link">
    <sensor name="tb3_imu" type="imu">
      <always_on>true</always_on>
      <update_rate>200</update_rate>
      <topic>imu</topic>
      <gz_frame_id>imu_link</gz_frame_id>
      <imu>
        <angular_velocity>
          <x>
            <noise type="gaussian">
              <mean>0.0</mean>
              <stddev>2e-4</stddev>
            </noise>
          </x>
          <y>
            <noise type="gaussian">
              <mean>0.0</mean>
              <stddev>2e-4</stddev>
            </noise>
          </y>
          <z>
            <noise type="gaussian">
              <mean>0.0</mean>
              <stddev>2e-4</stddev>
            </noise>
          </z>
        </angular_velocity>
        <linear_acceleration>
          <x>
            <noise type="gaussian">
              <mean>0.0</mean>
              <stddev>1.7e-2</stddev>
            </noise>
          </x>
          <y>
            <noise type="gaussian">
              <mean>0.0</mean>
              <stddev>1.7e-2</stddev>
            </noise>
          </y>
          <z>
            <noise type="gaussian">
              <mean>0.0</mean>
              <stddev>1.7e-2</stddev>
            </noise>
          </z>
        </linear_acceleration>
      </imu>
    </sensor>
  </gazebo>

  <gazebo>
    <plugin
      filename="gz-sim-diff-drive-system"
      name="gz::sim::systems::DiffDrive">
      <left_joint>wheel_left_joint</left_joint>
      <right_joint>wheel_right_joint</right_joint>
      <wheel_separation>0.287</wheel_separation>
      <wheel_radius>0.033</wheel_radius>
      <max_linear_acceleration>1</max_linear_acceleration>
      <min_linear_acceleration>-1</min_linear_acceleration>
      <max_angular_acceleration>2</max_angular_acceleration>
      <min_angular_acceleration>-2</min_angular_acceleration>
      <max_linear_velocity>0.46</max_linear_velocity>
      <min_linear_velocity>-0.46</min_linear_velocity>
      <max_angular_velocity>1.9</max_angular_velocity>
      <min_angular_velocity>-1.9</min_angular_velocity>
      <topic>/cmd_vel</topic>
      <odom_topic>/odom</odom_topic>
      <tf_topic>tf</tf_topic>
      <frame_id>odom</frame_id>
      <child_frame_id>base_footprint</child_frame_id>
      <odom_publish_frequency>25</odom_publish_frequency>
    </plugin>

    <plugin
      filename="gz-sim-pose-publisher-system"
      name="gz::sim::systems::PosePublisher">
      <publish_link_pose>true</publish_link_pose>
      <publish_sensor_pose>true</publish_sensor_pose>
      <publish_collision_pose>false</publish_collision_pose>
      <publish_visual_pose>false</publish_visual_pose>
      <publish_nested_model_pose>true</publish_nested_model_pose>
      <static_publisher>true</static_publisher>
      <use_pose_vector_msg>true</use_pose_vector_msg>
      <update_frequency>25</update_frequency>
      <static_update_frequency>25</static_update_frequency>
    </plugin>
  </gazebo>

</robot>
